<?xml version="1.0" encoding="utf-8"?>
<!-- =================================================================================== -->
<!-- |    This document was autogenerated by xacro from my_robot_integration.urdf.xacro | -->
<!-- |    EDITING THIS FILE BY HAND IS NOT RECOMMENDED                                 | -->
<!-- =================================================================================== -->
<!-- Name your robot here -->
<robot name="car">
  <link name="dummy"/>
  <link name="chassis">
    <inertial>
      <origin rpy="0 0 0" xyz="-0.13485 -1.1234E-17 0.18835"/>
      <mass value="34.466"/>
      <inertia ixx="0.61222" ixy="1.4442E-16" ixz="-0.25305" iyy="2.4932" iyz="-2.8489E-17" izz="2.8529"/>
    </inertial>
    <visual>
      <origin rpy="0 0 0" xyz="0 0 0"/>
      <geometry>
        <mesh filename="package://car/meshes/chassis.STL"/>
      </geometry>
      <material name="">
        <color rgba="0.79216 0.81961 0.93333 1"/>
      </material>
    </visual>
    <collision>
      <origin rpy="0 0 0" xyz="0 0 0"/>
      <geometry>
        <mesh filename="package://car/meshes/chassis.STL"/>
      </geometry>
    </collision>
  </link>
  <link name="fr_steer">
    <inertial>
      <origin rpy="0 0 0" xyz="1.1102E-16 -2.3592E-16 0.066279"/>
      <mass value="0.1817"/>
      <inertia ixx="0.00057325" ixy="5.6093E-21" ixz="-1.9024E-20" iyy="0.00057787" iyz="1.8306E-18" izz="5.889E-05"/>
    </inertial>
    <visual>
      <origin rpy="0 0 0" xyz="0 0 0"/>
      <geometry>
        <mesh filename="package://car/meshes/fr_steer.STL"/>
      </geometry>
      <material name="">
        <color rgba="0.79216 0.81961 0.93333 1"/>
      </material>
    </visual>
    <collision>
      <origin rpy="0 0 0" xyz="0 0 0"/>
      <geometry>
        <mesh filename="package://car/meshes/fr_steer.STL"/>
      </geometry>
    </collision>
  </link>
  <joint name="dummy_joint" type="fixed">
    <parent link="dummy"/>
    <child link="chassis"/>
  </joint>
  <joint name="fr_steer_joint" type="revolute">
    <origin rpy="0 0 0" xyz="0.254 -0.1016 0.0762"/>
    <parent link="chassis"/>
    <child link="fr_steer"/>
    <axis xyz="0 0 1"/>
    <limit effort="0" lower="0" upper="0" velocity="0"/>
  </joint>
  <link name="fr_wheel">
    <inertial>
      <origin rpy="0 0 0" xyz="4.996E-16 -0.10298 -5.5511E-16"/>
      <mass value="0.83238"/>
      <inertia ixx="0.0037033" ixy="1.183E-17" ixz="3.3604E-18" iyy="0.0053719" iyz="4.3262E-18" izz="0.0037033"/>
    </inertial>
    <visual>
      <origin rpy="0 0 0" xyz="0 0 0"/>
      <geometry>
        <mesh filename="package://car/meshes/fr_wheel.STL"/>
      </geometry>
      <material name="">
        <color rgba="0.79216 0.81961 0.93333 1"/>
      </material>
    </visual>
    <collision>
      <origin rpy="0 0 0" xyz="0 0 0"/>
      <geometry>
        <mesh filename="package://car/meshes/fr_wheel.STL"/>
      </geometry>
    </collision>
  </link>
  <joint name="fr_wheel_joint" type="continuous">
    <origin rpy="0 0 0" xyz="0 0 0.0254"/>
    <parent link="fr_steer"/>
    <child link="fr_wheel"/>
    <axis xyz="0 -1 0"/>
  </joint>
  <link name="fl_steer">
    <inertial>
      <origin rpy="0 0 0" xyz="-1.1102E-16 -2.3592E-16 0.066279"/>
      <mass value="0.1817"/>
      <inertia ixx="0.00057325" ixy="-5.2862E-21" ixz="-4.0214E-20" iyy="0.00057787" iyz="1.8525E-18" izz="5.889E-05"/>
    </inertial>
    <visual>
      <origin rpy="0 0 0" xyz="0 0 0"/>
      <geometry>
        <mesh filename="package://car/meshes/fl_steer.STL"/>
      </geometry>
      <material name="">
        <color rgba="0.79216 0.81961 0.93333 1"/>
      </material>
    </visual>
    <collision>
      <origin rpy="0 0 0" xyz="0 0 0"/>
      <geometry>
        <mesh filename="package://car/meshes/fl_steer.STL"/>
      </geometry>
    </collision>
  </link>
  <joint name="fl_steer_joint" type="revolute">
    <origin rpy="0 0 0" xyz="0.254 0.1016 0.0762"/>
    <parent link="chassis"/>
    <child link="fl_steer"/>
    <axis xyz="0 0 1"/>
    <limit effort="0" lower="0" upper="0" velocity="0"/>
  </joint>
  <link name="fl_wheel">
    <inertial>
      <origin rpy="0 0 0" xyz="5.5511E-16 0.10298 1.3184E-15"/>
      <mass value="0.83238"/>
      <inertia ixx="0.0037033" ixy="-1.1103E-17" ixz="-3.4411E-18" iyy="0.0053719" iyz="1.5824E-17" izz="0.0037033"/>
    </inertial>
    <visual>
      <origin rpy="0 0 0" xyz="0 0 0"/>
      <geometry>
        <mesh filename="package://car/meshes/fl_wheel.STL"/>
      </geometry>
      <material name="">
        <color rgba="0.79216 0.81961 0.93333 1"/>
      </material>
    </visual>
    <collision>
      <origin rpy="0 0 0" xyz="0 0 0"/>
      <geometry>
        <mesh filename="package://car/meshes/fl_wheel.STL"/>
      </geometry>
    </collision>
  </link>
  <joint name="fl_wheel_joint" type="continuous">
    <origin rpy="0 0 0" xyz="0 0 0.0254"/>
    <parent link="fl_steer"/>
    <child link="fl_wheel"/>
    <axis xyz="0 1 0"/>
  </joint>
  <link name="rear_axle">
    <inertial>
      <origin rpy="0 0 0" xyz="5.5511E-17 2.0893E-16 2.2204E-16"/>
      <mass value="1.7238"/>
      <inertia ixx="0.077136" ixy="2.0778E-16" ixz="-4.107E-19" iyy="0.010745" iyz="-1.6185E-16" izz="0.077136"/>
    </inertial>
    <visual>
      <origin rpy="0 0 0" xyz="0 0 0"/>
      <geometry>
        <mesh filename="package://car/meshes/rear_axle.STL"/>
      </geometry>
      <material name="">
        <color rgba="0.79216 0.81961 0.93333 1"/>
      </material>
    </visual>
    <collision>
      <origin rpy="0 0 0" xyz="0 0 0"/>
      <geometry>
        <mesh filename="package://car/meshes/rear_axle.STL"/>
      </geometry>
    </collision>
  </link>
  <joint name="rear_axle_joint" type="continuous">
    <origin rpy="0 0 0" xyz="-0.254 0 0.1016"/>
    <parent link="chassis"/>
    <child link="rear_axle"/>
    <axis xyz="0 -1 0"/>
  </joint>
  <transmission name="fr_steer">
    <type>transmission_interface/SimpleTransmission</type>
    <actuator name="motor1">
      <hardwareInterface>hardware_interface/EffortJointInterface</hardwareInterface>
      <mechanicalReduction>1</mechanicalReduction>
    </actuator>
    <joint name="fr_steer_joint">
      <hardwareInterface>hardware_interface/EffortJointInterface</hardwareInterface>
    </joint>
  </transmission>
  <transmission name="fl_steer">
    <type>transmission_interface/SimpleTransmission</type>
    <actuator name="motor2">
      <hardwareInterface>hardware_interface/EffortJointInterface</hardwareInterface>
      <mechanicalReduction>1</mechanicalReduction>
    </actuator>
    <joint name="fl_steer_joint">
      <hardwareInterface>hardware_interface/EffortJointInterface</hardwareInterface>
    </joint>
  </transmission>
  <transmission name="rear_axle">
    <type>transmission_interface/SimpleTransmission</type>
    <actuator name="motor3">
      <hardwareInterface>hardware_interface/EffortJointInterface</hardwareInterface>
      <mechanicalReduction>1</mechanicalReduction>
    </actuator>
    <joint name="rear_axle_joint">
      <hardwareInterface>hardware_interface/EffortJointInterface</hardwareInterface>
    </joint>
  </transmission>
  <transmission name="fr_wheel">
    <type>transmission_interface/SimpleTransmission</type>
    <actuator name="motor4">
      <hardwareInterface>hardware_interface/EffortJointInterface</hardwareInterface>
      <mechanicalReduction>1</mechanicalReduction>
    </actuator>
    <joint name="fr_wheel_joint">
      <hardwareInterface>hardware_interface/EffortJointInterface</hardwareInterface>
    </joint>
  </transmission>
  <transmission name="fl_wheel">
    <type>transmission_interface/SimpleTransmission</type>
    <actuator name="motor5">
      <hardwareInterface>hardware_interface/EffortJointInterface</hardwareInterface>
      <mechanicalReduction>1</mechanicalReduction>
    </actuator>
    <joint name="fl_wheel_joint">
      <hardwareInterface>hardware_interface/EffortJointInterface</hardwareInterface>
    </joint>
  </transmission>
  <link name="base_laser">
    <inertial>
      <origin rpy="0 0 0" xyz="-0.00029774 0.0066667 0.00013047"/>
      <mass value="0.15717"/>
      <inertia ixx="6.7885E-05" ixy="-1.3987E-07" ixz="-8.1554E-07" iyy="0.00013173" iyz="-9.0932E-08" izz="7.1972E-05"/>
    </inertial>
    <visual>
      <origin rpy="0 0 0" xyz="0 0 0"/>
      <geometry>
        <mesh filename="package://ydlidar_ros/meshes/ydlidar.dae"/>
      </geometry>
      <material name="">
        <color rgba="0.64706 0.61961 0.58824 1"/>
      </material>
    </visual>
    <collision>
      <origin rpy="0 0 0" xyz="0 0 0"/>
      <geometry>
        <mesh filename="package://ydlidar_ros/meshes/ydlidar.dae"/>
      </geometry>
    </collision>
  </link>
  <link name="laser_frame">
    <inertial>
      <origin rpy="0 0 0" xyz="-0.00036659 0.00064155 -0.00027052"/>
      <mass value="0.25482"/>
      <inertia ixx="8.9194E-05" ixy="1.8116E-07" ixz="3.6435E-08" iyy="0.00018279" iyz="2.423E-07" izz="0.00011103"/>
    </inertial>
    <!--visual>
      <origin
        xyz="0 0 0"
        rpy="0 0 0" />
      <geometry>
        <mesh
          filename="package://ydlidar_ros/meshes/ydlidar.dae" />
      </geometry>
      <material
        name="">
        <color
          rgba="0.64706 0.61961 0.58824 1" />
      </material>
    </visual-->
    <!--collision>
      <origin
        xyz="0 0 0"
        rpy="0 0 0" />
      <geometry>
        <mesh
          filename="package://ydlidar_ros/meshes/ydlidar.dae" />
      </geometry>
    </collision-->
  </link>
  <joint name="laser_joint" type="fixed">
    <origin rpy="0 0 0" xyz="0 0 0.03172"/>
    <parent link="base_laser"/>
    <child link="laser_frame"/>
    <axis xyz="0 0 0"/>
  </joint>
  <!-- Add your gazebo sensors here -->
  <gazebo reference="base_laser">
    <!-- <gravity>true</gravity> -->
    <!-- Gazebo has fixed set of Sensors types. Check them out here <> -->
    <sensor name="laser" type="ray">
      <!-- Add in your sensor characteristics -->
      <pose> 0 0 0 0 0 0 </pose>
      <visualise>true</visualise>
      <update_rate>40</update_rate>
      <!-- <always_on>true</always_on> -->
      <ray>
        <scan>
          <horizontal>
            <samples>720</samples>
            <resolution>1</resolution>
            <min_angle>-1.570796</min_angle>
            <max_angle>1.570796</max_angle>
          </horizontal>
        </scan>
        <range>
          <min>0.10</min>
          <max>30.0</max>
          <resolution>0.01</resolution>
        </range>
        <noise>
          <type>gaussian</type>
          <mean>0.0</mean>
          <stddev>0.01</stddev>
        </noise>
      </ray>
      <plugin filename="libgazebo_ros_laser.so" name="gazebo_ros_head_hokuyo_controller">
        <!-- Use topic name as /my_robot/scan -->
        <topicName>/car/scan</topicName>
        <frameName>laser_frame</frameName>
      </plugin>
    </sensor>
  </gazebo>
  <!--  Gazebo plugin for control here is already added for you -->
  <gazebo>
    <plugin filename="libgazebo_ros_control.so" name="gazebo_ros_control">
      <robotNamespace>/car</robotNamespace>
      <robotSimType>gazebo_ros_control/DefaultRobotHWSim</robotSimType>
      <legacyModeNS>true</legacyModeNS>
    </plugin>
  </gazebo>
  <!-- Create a joint between your robot and sensor -->
  <joint name="car_lidar" type="fixed">
    <axis xyz="0 1 0"/>
    <parent link="chassis"/>
    <child link="base_laser"/>
    <origin rpy="1.570796 0 0" xyz="0.254 -0.254 0"/>
  </joint>
</robot>
